Workbook

Sheet Valor por dia de pagamento
E1: Entraram e permanecem | J1: Entraram e já sairam | N1: Total de entrada | Q1: Total de saida
A3: Soma de Valor 2025 | E3: Soma de QDE DE CÃES | J3: Soma de QDE DE CÃES | Q3: Soma de QDE DE CÃES
A4: Dia | B4: Total | E4: Ano | F4: Mês | G4: Total | J4: Ano | K4: Mês | L4: Total | O4: =SUM(O6:O22) -> 407 | Q4: Ano Saída | R4: Mês Saida | S4: Total
A5: 1 | B5: 2068.75 | E5: 2011 | F5: 6 | G5: 1 | J5: 2009 | K5: 8 | L5: 1 | Q5: 2017 | R5: 1 | S5: 7
A6: 2 | B6: 5610.5525 | E6: 2011 Total | G6: 1 | J6: 2009 Total | L6: 1 | R6: 2 | S6: 1
A7: 3 | B7: 714 | E7: (vazio) | J7: 2010 | K7: 10 | L7: 2 | N7: 2011 | O7: =GETPIVOTDATA("QDE DE CÃES",$E$3,"Ano",2011)+GETPIVOTDATA("QDE DE CÃES",$J$3,"Ano",2011) -> 5 | R7: 3 | S7: 1
A8: 4 | B8: 1357.95 | E8: 2014 | F8: 4 | G8: 5 | K8: 11 | L8: 5 | N8: 2012 | O8: =GETPIVOTDATA("QDE DE CÃES",$J$3,"Ano",2012) -> 12 | R8: 4 | S8: 6
A9: 5 | B9: 714 | E9: 2014 Total | G9: 5 | J9: 2010 Total | L9: 7 | N9: 2013 | O9: =GETPIVOTDATA("QDE DE CÃES",$J$3,"Ano",2013) -> 6 | R9: 5 | S9: 1
A10: 8 | B10: 1392.3 | E10: 2015 | F10: 5 | G10: 1 | J10: 2011 | K10: 1 | L10: 1 | N10: 2014 | O10: =GETPIVOTDATA("QDE DE CÃES",$E$3,"Ano",2014)+GETPIVOTDATA("QDE DE CÃES",$J$3,"Ano",2014) -> 27 | R10: 6 | S10: 4
A11: 9 | B11: 2249.1 | F11: 9 | G11: 2 | K11: 5 | L11: 1 | N11: 2015 | O11: =GETPIVOTDATA("QDE DE CÃES",$E$3,"Ano",2015)+GETPIVOTDATA("QDE DE CÃES",$J$3,"Ano",2015) -> 26 | R11: 7 | S11: 4
A12: 10 | B12: 4110.6 | F12: 11 | G12: 1 | K12: 6 | L12: 1 | N12: 2016 | O12: =GETPIVOTDATA("QDE DE CÃES",$E$3,"Ano",2016)+GETPIVOTDATA("QDE DE CÃES",$J$3,"Ano",2016) -> 50 | R12: 8 | S12: 2
A13: 11 | B13: 714 | E13: 2015 Total | G13: 4 | K13: 9 | L13: 1 | N13: 2017 | O13: =GETPIVOTDATA("QDE DE CÃES",$E$3,"Ano",2017)+GETPIVOTDATA("QDE DE CÃES",$J$3,"Ano",2017) -> 37 | R13: 9 | S13: 2
A14: 12 | B14: 2710.92 | E14: 2016 | F14: 1 | G14: 1 | J14: 2011 Total | L14: 4 | N14: 2018 | O14: =GETPIVOTDATA("QDE DE CÃES",$E$3,"Ano",2018)+GETPIVOTDATA("QDE DE CÃES",$J$3,"Ano",2018) -> 34 | R14: 10 | S14: 1
A15: 13 | B15: 3677.1 | F15: 10 | G15: 1 | J15: 2012 | K15: 1 | L15: 1 | N15: 2019 | O15: =GETPIVOTDATA("QDE DE CÃES",$E$3,"Ano",2019)+GETPIVOTDATA("QDE DE CÃES",$J$3,"Ano",2019) -> 32 | R15: 12 | S15: 8
A16: 14 | B16: 1484.96 | E16: 2016 Total | G16: 2 | K16: 2 | L16: 1 | N16: 2020 | O16: =GETPIVOTDATA("QDE DE CÃES",$E$3,"Ano",2020)+GETPIVOTDATA("QDE DE CÃES",$J$3,"Ano",2020) -> 38 | Q16: 2017 Soma | S16: 37
A17: 16 | B17: 2026.5 | E17: 2017 | F17: 5 | G17: 1 | K17: 3 | L17: 1 | N17: 2021 | O17: =GETPIVOTDATA("QDE DE CÃES",$E$3,"Ano",2021)+GETPIVOTDATA("QDE DE CÃES",$J$3,"Ano",2021) -> 44 | Q17: 2018 | R17: 1 | S17: 2
A18: 17 | B18: 2852.43 | F18: 8 | G18: 1 | K18: 4 | L18: 2 | N18: 2022 | O18: =GETPIVOTDATA("QDE DE CÃES",$E$3,"Ano",2022)+GETPIVOTDATA("QDE DE CÃES",$J$3,"Ano",2022) -> 46 | R18: 2 | S18: 4
A19: 18 | B19: 749.7 | E19: 2017 Total | G19: 2 | K19: 6 | L19: 2 | N19: 2023 | O19: =GETPIVOTDATA("QDE DE CÃES",$E$3,"Ano",2023)+GETPIVOTDATA("QDE DE CÃES",$J$3,"Ano",2023) -> 20 | R19: 3 | S19: 1
A20: 19 | B20: 3624.6 | E20: 2018 | F20: 1 | G20: 1 | K20: 9 | L20: 1 | N20: 2024 | O20: =GETPIVOTDATA("QDE DE CÃES",$E$3,"Ano",2024)+GETPIVOTDATA("QDE DE CÃES",$J$3,"Ano",2024) -> 23 | R20: 4 | S20: 3
A21: 20 | B21: 714 | F21: 9 | G21: 1 | K21: 11 | L21: 1 | N21: 2025 | O21: =GETPIVOTDATA("QDE DE CÃES",$E$3,"Ano",2025) -> 7 | R21: 5 | S21: 1
A22: 21 | B22: 1544.03 | E22: 2018 Total | G22: 2 | K22: 12 | L22: 3 | R22: 6 | S22: 6
A23: 22 | B23: 714 | E23: 2019 | F23: 4 | G23: 1 | J23: 2012 Total | L23: 12 | R23: 7 | S23: 2
A24: 23 | B24: 1463.7 | F24: 12 | G24: 1 | J24: 2013 | K24: 1 | L24: 1 | R24: 8 | S24: 1
A25: 24 | B25: 2109.18 | E25: 2019 Total | G25: 2 | K25: 2 | L25: 1 | R25: 9 | S25: 2
A26: 25 | B26: 2249.1 | E26: 2020 | F26: 5 | G26: 2 | K26: 7 | L26: 1 | R26: 10 | S26: 4
A27: 27 | B27: 714 | F27: 10 | G27: 1 | K27: 8 | L27: 1 | R27: 11 | S27: 2
A28: 29 | B28: 4174.67 | F28: 12 | G28: 1 | K28: 9 | L28: 1 | R28: 12 | S28: 2
A29: 30 | B29: 2213.4 | E29: 2020 Total | G29: 4 | K29: 11 | L29: 1 | Q29: 2018 Soma | S29: 30
A30: Total Geral | B30: 51953.542 | E30: 2021 | F30: 1 | G30: 3 | J30: 2013 Total | L30: 6 | Q30: 2019 | R30: 1 | S30: 3
F31: 5 | G31: 3 | J31: 2014 | K31: 2 | L31: 1 | R31: 2 | S31: 2
F32: 6 | G32: 1 | K32: 3 | L32: 1 | R32: 3 | S32: 3
F33: 8 | G33: 1 | K33: 4 | L33: 3 | R33: 4 | S33: 2
F34: 10 | G34: 3 | K34: 5 | L34: 2 | R34: 5 | S34: 2
F35: 11 | G35: 1 | K35: 7 | L35: 3 | R35: 6 | S35: 2
F36: 12 | G36: 1 | K36: 8 | L36: 6 | R36: 7 | S36: 8
E37: 2021 Total | G37: 13 | K37: 9 | L37: 4 | R37: 8 | S37: 3
E38: 2022 | F38: 3 | G38: 2 | K38: 10 | L38: 2 | R38: 10 | S38: 4
F39: 4 | G39: 1 | J39: 2014 Total | L39: 22 | Q39: 2019 Soma | S39: 29
F40: 8 | G40: 1 | J40: 2015 | K40: 1 | L40: 2 | Q40: 2020 | R40: 1 | S40: 3
F41: 12 | G41: 1 | K41: 2 | L41: 2 | R41: 2 | S41: 4
...

Sheet Lista
A1: Nome | B1: RG | C1: CPF | D1: Telefone | E1: Endereço | F1: Bairro | G1: Cidade | H1: Cep | I1: Email | J1: Nome do cão | K1: QDE DE CÃES | L1: Data de pagamento | M1: Dia | N1: Mês | O1: Ano | P1: Valor 2019 e 2020 | Q1: Valor 2021 | R1: Valor 2022 | S1: Valor 2023 | T1: Valor 2024 | U1: Valor 2025 | V1: Valor 2026 | W1: =SUM(K:K) -> 71 | X1: =SUM(V:V) -> 54326.558 | Y1: =X1/W1 -> 765.16278 | AC1: adicional
A2: ANA PAULA DE OLIVEIRA VIEIRA | B2: 50320046-3 | C2: 042486506-81 | D2: 11 3763-3068 | E2: RUA EULO MARONI N°171 BLC05 APTO 31 | F2: VILA LAGEADO | G2: São Paulo | H2: 05338-100 | I2: apovieira@yahoo.com | J2: LUNA | K2: 1 | L2: 40715 | M2: =DAY(L2) -> 21 | N2: =MONTH(L2) -> 6 | O2: =YEAR(L2) -> 2011 | P2: 1077.5342 | Q2: 620 | R2: 686.42866 | S2: =R2*1.09677 -> 752.85436 | T2: =ROUNDUP(S2*1.05,2) -> 790.5 | U2: =ROUNDUP(T2*1.05,2) -> 830.03 | V2: =U2*1.075 -> 892.28225 | W2: =6*V2 -> 5353.6935 | Y2: EMITIDO BOLETOS DE JAN A JUN26 | AE2: ANA PAULA DE OLIVEIRA VIEIRA
A3: NEIVA DOURADO MARTINS MENDES | B3: 18420741 | C3: 030283108-80 | D3: 11 4121-7832 | E3: RUA DOMICIANO ROSSI 600 APTO193 H | F3: SÃO BERNARDO DO CAMPO | G3: SÃO BERNARDO DO CAMPO | H3: 09726-121 | I3: neiva.mendes@uol.com.br | J3: BELINHA , FAROFA, PIPOCA E NINA | K3: 4 | L3: 41731 | M3: =DAY(L3) -> 2 | N3: =MONTH(L3) -> 4 | O3: =YEAR(L3) -> 2014 | P3: 3334.7601 | Q3: 4017.44 | R3: 4447.8806 | S3: 4268.51 | T3: 3841.66 | U3: =((T3/6)*K3)*1.05 -> 2689.162 | V3: =U3*1.075 -> 2890.8491 | W3: =6*V3 -> 17345.095 | X3: DDA | Y3: EMITIDO BOLETOS JAN A DEZ26 | AE3: NEIVA DOURADO MARTINS MENDES
A4: KARINA ROLIM PEREIRA DOS SANTOS | B4: 43618716 | C4: 316771568-56 | D4: 11 2309-9402 | E4: RUA ANTONIO AGGIO,400 APTO 41 | F4: JARDIM AMPLIAÇÃO | G4: São Paulo | H4: 05713-420 | I4: karinarolim@hotmail.com | J4: VALENTINO | K4: 1 | L4: 42154 | M4: =DAY(L4) -> 30 | N4: =MONTH(L4) -> 5 | O4: =YEAR(L4) -> 2015 | P4: 530.00002 | Q4: 560.00002 | R4: 620.0001 | S4: =R4*1.09677 -> 679.99751 | T4: =ROUNDUP(S4*1.05,2) -> 714 | U4: =ROUNDUP(T4*1.05,2) -> 749.7 | V4: =U4*1.075 -> 805.9275 | W4: =6*V4 -> 4835.565 | Y4: EMITIDO BOLETOS DE JAN A JUN26 | AE4: KARINA ROLIM PEREIRA DOS SANTOS
A5: BEATRIZ MOURA XAVIER GARCIA | B5: 18.432.729-5 | C5: 524.372.148-44 | D5: 11 98688-2273 | E5: AVENIDA PAVÃO 231 APTO 164 B | F5: INDIANOPOLIS | G5: São Paulo | H5: 04516-010 | I5: biamxgarcia@gmail.com | J5: DUDA E FILO | K5: 2 | L5: 42264 | M5: =DAY(L5) -> 17 | N5: =MONTH(L5) -> 9 | O5: =YEAR(L5) -> 2015 | P5: 1656.25 | Q5: 1064 | R5: 1767.0002 | S5: 1292 | T5: =ROUNDUP(S5*1.05,2) -> 1356.6 | U5: =ROUNDUP(T5*1.05,2) -> 1424.43 | V5: =U5*1.075 -> 1531.2622 | W5: =3*V5 -> 4593.7868 | Y5: EMITIDO BOLETOS JAN A JUN26 | AE5: LUCIA HELENA MOURA XAVIER GARCIA
A6: SAMANTHA SARAIVA | B6: MG2087209 | C6: 011750776-82 | D6: 11 942492977 | E6: RUA PEIXOTO GOMIDE, 1769 APTO 31 | F6: JARDIM PAULISTA | G6: São Paulo | H6: 01409-000 | I6: samantha.saraiva@gmail.com | J6: VIVIAN | K6: 1 | L6: 42322 | M6: =DAY(L6) -> 14 | N6: =MONTH(L6) -> 11 | O6: =YEAR(L6) -> 2015 | P6: 595.5 | Q6: 629.20755 | R6: 696.62273 | S6: =R6*1.09677 -> 764.03491 | T6: =ROUNDUP(S6*1.05,2) -> 802.24 | U6: =ROUNDUP(T6*1.05,2) -> 842.36 | V6: =U6*1.075 -> 905.537 | W6: =6*V6 -> 5433.222 | X6: =W6/6 -> 905.537 | Y6: EMITIDO BOLETOS JAN A JUN26 | AB6: SOMAR 65,50 Frontline | AE6: SAMANTHA SARAIVA
A7: CECILIA MARIA GRANATO DE ANDRADE | B7: 35079126 | C7: 007.326.738-44 | D7: 11 99183-8895 | E7: RUA FERNANDES MOREIRA, 582 APTO 142 | F7: CHACARA SANTO ANTONIO | G7: São Paulo | H7: 04716-001 | I7: ceciliagranato@gmail.com | J7: HOMER | K7: 1 | L7: 42393 | M7: =DAY(L7) -> 24 | N7: =MONTH(L7) -> 1 | O7: =YEAR(L7) -> 2016 | P7: 530.00002 | Q7: 560.00002 | R7: 620.0001 | S7: =R7*1.09677 -> 679.99751 | T7: =ROUNDUP(S7*1.05,2) -> 714 | U7: =ROUNDUP(T7*1.05,2) -> 749.7 | V7: =U7*1.075 -> 805.9275 | W7: =6*V7 -> 4835.565 | Y7: EMITIDO BOLETOS DE JAN A JUN26 | AE7: CECILIA MARIA GRANATO DE ANDRADE
A8: GILBERTO ARMENTANO CLARK REIS | B8: 777892 | C8: 083.748.368-90 | D8: 11 31293591 | E8: RUA AUGUSTA 1460 APTO 32 | F8: CONSOLAÇÃO | G8: SÃO PAULO | H8: 01304-001 | I8: garmentano@uol.com.br | J8: LOLLA | K8: 1 | L8: 42656 | M8: =DAY(L8) -> 13 | N8: =MONTH(L8) -> 10 | O8: =YEAR(L8) -> 2016 | P8: 530.00002 | Q8: 560.00002 | R8: 620.0001 | S8: =R8*1.09677 -> 679.99751 | T8: =ROUNDUP(S8*1.05,2) -> 714 | U8: =ROUNDUP(T8*1.05,2) -> 749.7 | V8: =U8*1.075 -> 805.9275 | W8: =6*V8 -> 4835.565 | Y8: EMITIDO BOLETOS JAN A JUN26 | AE8: GILBERTO ARMENTANO CLARK REIS
A9: VITOR BARBANTI PAZIN | B9: 46.517.691-4 | C9: 400.762.228-02 | D9: 11 2682 9229 | E9: RUA GUARAS 17 | F9: VILA ARAGUAIA | G9: SÃO PAULO | H9: 03735-120 | I9: vitor.pazin@gmail.com | J9: BOLT | K9: 1 | L9: 42867 | M9: =DAY(L9) -> 12 | N9: =MONTH(L9) -> 5 | O9: =YEAR(L9) -> 2017 | P9: 530.00002 | Q9: 560.00002 | R9: 620.0001 | S9: =R9*1.09677 -> 679.99751 | T9: =ROUNDUP(S9*1.05,2) -> 714 | U9: =ROUNDUP(T9*1.05,2) -> 749.7 | V9: =U9*1.075 -> 805.9275 | W9: =6*V9 -> 4835.565 | Y9: EMITIDO BOLETOS JAN A JUN26 | AE9: VITOR BARBANTI PAZIN
A10: ANA CLAUDIA CUNHA TRAVASSOS | B10: 141308254 | C10: 245768928-78 | D10: 11-982446128 | E10: AV. GUILHERME DUMONT VILLARES, 2001 APTO 13 | F10: JD LONDRINA | G10: SÃO PAULO | H10: 05640-003 | I10: acctravassos@gmail.com | J10: MEL | K10: 1 | L10: 42972 | M10: =DAY(L10) -> 25 | N10: =MONTH(L10) -> 8 | O10: =YEAR(L10) -> 2017 | P10: 530.00002 | Q10: 560.00002 | R10: 620.0001 | S10: =R10*1.09677 -> 679.99751 | T10: =ROUNDUP(S10*1.05,2) -> 714 | U10: =ROUNDUP(T10*1.05,2) -> 749.7 | V10: =U10*1.075 -> 805.9275 | W10: =6*V10 -> 4835.565 | Y10: EMITIDO BOLETOS DE JAN A JUN26 | AE10: ANA CLAUDIA CUNHA TRAVASSOS
A11: MONICA DOS SANTOS COUTINHO | B11: 18870928-9 | C11: 091.175.968-90 | D11: 11 9 856-8838 | E11: RUA PROFESSOR JOAO ARRUDA 134 APTO 54 | F11: PERDIZES | G11: SÃO PAULO | H11: 05012-000 | I11: monicascoutinho@live.com | J11: FAÍSCA | K11: 1 | L11: 43113 | M11: =DAY(L11) -> 13 | N11: =MONTH(L11) -> 1 | O11: =YEAR(L11) -> 2018 | P11: 530.00002 | Q11: 560.00002 | R11: 620.0001 | S11: =R11*1.09677 -> 679.99751 | T11: =ROUNDUP(S11*1.05,2) -> 714 | U11: =ROUNDUP(T11*1.05,2) -> 749.7 | V11: =U11*1.075 -> 805.9275 | W11: =6*V11 -> 4835.565 | Y11: EMITIDO BOLETOS JAN A JUN26 | Z11: 1937.9928 | AA11: =Z11/3 -> 645.99759 | AB11: =AA11/30 -> 21.533253 | AC11: =AB11*4 -> 86.133011 | AE11: MONICA DOS SANTOS COUTINHO
A12: ANTONIO CARLOS SOBRINHO | B12: 205114313 | C12: 146395318-69 | D12: 1198457-4196 | E12: SILVEIRA RODRIGUES, 23 APTO 32 B | F12: SILICIANO | G12: SÃO PAULO | H12: 05048-070 | I12: acsobrinho@gmail.com | J12: NINO | K12: 1 | L12: 43344 | M12: =DAY(L12) -> 1 | N12: =MONTH(L12) -> 9 | O12: =YEAR(L12) -> 2018 | P12: 530 | Q12: 560 | R12: 620.00008 | S12: =R12*(1+9.677%) -> 679.99749 | T12: =ROUNDUP(S12*1.05,2) -> 714 | U12: =ROUNDUP(T12*1.05,2) -> 749.7 | V12: =U12*1.075 -> 805.9275 | W12: =6*V12 -> 4835.565 | Y12: EMITIDO BOLETOS JAN A DEZ26 | AA12: =Z11-AA11 -> 1291.9952 | AC12: =AA11-AC11 -> 559.86457 | AE12: ANTONIO CARLOS SOBRINHO
A13: ADRIANA RODRIGUES LOPEZ HERNANDEZ | B13: 23271188-4 | C13: 181.646.918-10 | D13: 112261-1855 | E13: RUA SANTO ADALBERTO 207 | F13: JARDIM FRANCA | G13: SÃO PAULO | H13: 02338-000 | I13: adrianarlh@bol.com.br | J13: SNOOPY | K13: 1 | L13: 43800 | M13: =DAY(L13) -> 1 | N13: =MONTH(L13) -> 12 | O13: =YEAR(L13) -> 2019 | P13: 450 | Q13: 475.4717 | R13: 526.41516 | S13: =R13*(1+9.677%) -> 577.35636 | T13: =ROUNDUP(S13*1.05,2) -> 606.23 | U13: =ROUNDUP(T13*1.05,2) -> 636.55 | V13: =U13*1.075 -> 684.29125 | W13: =6*V13 -> 4105.7475 | Y13: EMITIDO BOLETOS JAN A DEZ26 | AE13: ADRIANA RODRIGUES LOPEZ HERNANDEZ
A14: ANTONIO CARLOS DE OLIVEIRA CARNEIRO | B14: 181222590 | C14: 15196219811 | D14: 11 976143422 | E14: AV ESCOLA POLITENICA APTO 224 C1 | F14: PARQUE DOS PRINCIPES | G14: SÃO PAULO | H14: 5350000 | I14: a_carneiro@ig.com.br | J14: FRED | K14: 1 | L14: 43955 | M14: =DAY(L14) -> 4 | N14: =MONTH(L14) -> 5 | O14: =YEAR(L14) -> 2020 | P14: 960 | Q14: 1014.3396 | R14: 1123.019 | S14: =R14*(1+9.677%) -> 1231.6936 | T14: =ROUNDUP(S14*1.05,2) -> 1293.28 | U14: =ROUNDUP(T14*1.05,2)/2 -> 678.975 | V14: =U14*1.075 -> 729.89813 | W14: =6*V14 -> 4379.3888 | Y14: EMITIDO BOLETOS JAN A DEZ26 | AE14: ANTONIO CARLOS DE OLIVEIRA CARNEIRO
A15: MARCIA DE PINHO VIEIRA | B15: 172619014 | C15: 102004198-62 | D15: 11 9 9918-8301 | E15: AV. WASHINGTON LUÍS 1576 APTO 264 A | F15: SANTO AMARO | G15: SÃO PAULO | H15: 04662-902 | I15: marciapvieira@hotmail.com | J15: LOBINHO | K15: 1 | L15: 44128 | M15: =DAY(L15) -> 24 | N15: =MONTH(L15) -> 10 | O15: =YEAR(L15) -> 2020 | P15: 1160 | Q15: 1160 | R15: 1124.2859 | S15: =R15*1.09677 -> 1233.083 | T15: =ROUNDUP(S15*1.05,2) -> 1294.74 | U15: =ROUNDUP(T15*1.05,2)/2 -> 679.74 | V15: =U15*1.075 -> 730.7205 | W15: =6*V15 -> 4384.323 | Y15: EMITIDO BOLETOS DE JAN A JUN26 | Z15: INCLUSO COLEIRA E VERMIFUGO | AE15: MARCIA DE PINHO VIEIRA
A16: CRISTINA TAVARES DA SILVA | B16: W643182-1 | C16: 852.078.618-91 | D16: 11 9 8168-1717 | E16: RUA MARCOS LOPES 272 APTO 41 E | F16: VILA NOVA CONCEIÇÃO | G16: SÃO PAULO | H16: 04513-080 | I16: cristina.tavares7@gmail.com | J16: IGOR | K16: 1 | L16: 44204 | M16: =DAY(L16) -> 8 | N16: =MONTH(L16) -> 1 | O16: =YEAR(L16) -> 2021 | Q16: 960 | R16: 1062.8573 | S16: 582.85 | T16: =ROUNDUP(S16*1.05,2) -> 612 | U16: =ROUNDUP(T16*1.05,2) -> 642.6 | V16: =U16*1.075 -> 690.795 | W16: =6*V16 -> 4144.77 | Y16: EMITIDO BOLETOS JAN A DEZ26 | AE16: CRISTINA TAVARES DA SILVA
A17: WILSON MELGES ANTUNES | B17: 44643971 | C17: 371.085.488-10 | D17: 19 9 9372-6303 | E17: RUA JOAQUIM DE SEABRA 234 PARQUE RESIDENCIAL NOVA CANAÃ | F17: MOGI GUAÇU | G17: SÃO PAULO | H17: 13848-622 | I17: wilson.m.antunes@hotmail.com | J17: ZOE | K17: 1 | L17: 44206 | M17: =DAY(L17) -> 10 | N17: =MONTH(L17) -> 1 | O17: =YEAR(L17) -> 2021 | Q17: 480 | R17: 531.42864 | S17: =R17*(1+9.677%) -> 582.85499 | T17: =ROUNDUP(S17*1.05,2) -> 612 | U17: =ROUNDUP(T17*1.05,2) -> 642.6 | V17: =U17*1.075 -> 690.795 | W17: =6*V17 -> 4144.77 | Y17: EMITIDO BOLETOS JAN A DEZ26 | AE17: WILSON MELGES ANTUNES
A18: RICARDO TARGINO NETO | B18: 46697224 | C18: 379.547.618-60 | D18: 11 9 8909-6203 | E18: RUA ANTONIETA LEITÃO 161 AP 112 | F18: FREGUESIA DO Ó | G18: SÃO PAULO | H18: 02925-160 | I18: ricardo@adolfoneto.com.br | J18: PAMELA, ROSSI | K18: 2 | L18: 44345 | M18: =DAY(L18) -> 29 | N18: =MONTH(L18) -> 5 | O18: =YEAR(L18) -> 2021 | Q18: 1900 | R18: 2103.5717 | S18: =R18*1.09677 -> 2307.1343 | T18: 1816.875 | U18: =ROUNDUP(T18*1.05,2) -> 1907.72 | V18: 1367.1993 | W18: =6*V18 -> 8203.196 | Y18: EMITIDO BOLETOS DE JAN A JUN26 | Z18: SEM O FORNECIMENTO DE PRODUTOS | AE18: SUELEN CINTIA TARGINO NETO
A19: DANIELA LUCAS PEDRO | B19: 47.599.094-8 | C19: 403647498-73 | D19: 11 56773454 | E19: RUA BELMIRO ZANETTI ESTEVES, 223 CASA 2 | F19: VILA MIRA | G19: SÃO PAULO | H19: 04377-060 | I19: danishadowcat@yahoo.com.br | J19: VALENTINA | K19: 1 | L19: 44359 | M19: =DAY(L19) -> 12 | N19: =MONTH(L19) -> 6 | O19: =YEAR(L19) -> 2021 | Q19: 450 | R19: 500 | S19: =R19*1.0968 -> 548.39999 | T19: =ROUNDUP(S19*1.05,2) -> 575.82 | U19: =ROUNDUP(T19*1.05,2) -> 604.62 | V19: =U19*1.075 -> 649.9665 | W19: =6*V19 -> 3899.799 | Y19: EMITIDO BOLETOS JAN A JUN26 | Z19: SEM O FORNECIMENTO DE PRODUTOS | AE19: DANIELA LUCAS PEDRO
A20: ARIANE BONAFEDE | B20: 332.232.73 | C20: 343.730.938-22 | D20: 11 97554-8446 | E20: RUA REGO BARROS 1155 BLC A APTO 115 | F20: JARDIM VILA FORMOSA | G20: São Paulo | H20: 03460-000 | I20: ariane.bonafede@yahoo.com.br | J20: SHEIKE | K20: 1 | L20: 44438 | M20: =DAY(L20) -> 30 | N20: =MONTH(L20) -> 8 | O20: =YEAR(L20) -> 2021 | Q20: 560 | R20: 620.00008 | S20: =R20*1.09677 -> 679.99749 | T20: =ROUNDUP(S20*1.05,2) -> 714 | U20: =ROUNDUP(T20*1.05,2) -> 749.7 | V20: =U20*1.075 -> 805.9275 | W20: =6*V20 -> 4835.565 | Y20: EMITIDO BOLETOS DE JAN A JUN26 | AE20: ARIANE BONAFEDE
A21: ROSENI ANDREU DE OLIVEIRA | B21: 285963818 | C21: 192.535.158-05 | D21: 11 9 5305-0888 | E21: RUA ANHAIA, 439 | F21: VILA CURUCA | G21: SANTO ANDRÉ | H21: 09280-490 | I21: ga.abi@hotmail.com | J21: KILLER, SAMANTA E ZOE | K21: 3 | L21: 44478 | M21: =DAY(L21) -> 9 | N21: =MONTH(L21) -> 10 | O21: =YEAR(L21) -> 2021 | Q21: 1680 | R21: 1860 | S21: =R21*(1+9.677%) -> 2039.9922 | T21: =ROUNDUP(S21*1.05,2) -> 2142 | U21: =ROUNDUP(T21*1.05,2) -> 2249.1 | V21: =U21*1.075 -> 2417.7825 | W21: =6*V21 -> 14506.695 | Y21: EMITIDO BOLETOS JAN A DEZ26 | AE21: ROSENI ANDREU DE OLIVEIRA
A22: HANNA AMBACK ZAMARIAN | B22: 338482428 | C22: 407.731.478-02 | D22: 11 95071-1178 | E22: RUA FIAÇÃO DA SAÚDE 260 APTO 138 BLC C3 | F22: MIRANDÓPOLIS | G22: SÃO PAULO | H22: 04144-900 | I22: hannamfigueiredo@gmail.com | J22: VITOR | K22: 1 | L22: 44538 | M22: =DAY(L22) -> 8 | N22: =MONTH(L22) -> 12 | O22: =YEAR(L22) -> 2021 | Q22: 560 | R22: 620 | S22: =R22*(1+9.677%) -> 679.9974 | T22: =ROUNDUP(S22*1.05,2) -> 714 | U22: =ROUNDUP(T22*1.05,2) -> 749.7 | V22: =U22*1.075 -> 805.9275 | W22: =6*V22 -> 4835.565 | Y22: EMITIDO BOLETOS JAN A DEZ26 | AE22: HANNA AMBACK ZAMARIAN
A23: MARIA GORETTI BEKER FERREIRA | B23: 69832250 | C23: 186.271.658-74 | D23: 11 93272-3227 | E23: ALAMEDA DAS SERINGUEIRAS 229 (MORADA DOS PINHEIROS) | F23: ALDEIA DA SERRA | G23: SANTANA DE PARNAIBA | H23: 06519-325 | I23: bekergoretti@gmail.com | J23: LORD E LOBO | K23: 2 | L23: 44645 | M23: =DAY(L23) -> 25 | N23: =MONTH(L23) -> 3 | O23: =YEAR(L23) -> 2022 | R23: 1240 | S23: =R23*1.09677 -> 1359.9948 | T23: =ROUNDUP(S23*1.05,2) -> 1428 | U23: =ROUNDUP(T23*1.05,2) -> 1499.4 | V23: =U23*1.075 -> 1611.855 | W23: =6*V23 -> 9671.13 | Y23: EMITIDO BOLETOS DE JAN A JUN26 | AE23: MARIA GORETTI BEKER FERREIRA
A24: EDUARDO COSTA GARCIA PEREZ | C24: 395.310.868-93 | D24: 35 3899401153 | E24: AVENIDA ROUXINOL 418 APTO 41 | F24: INDIANOPOLIS | G24: SÃO PAULO | H24: 04516-000 | I24: eduardocgperez@uol.com.br | J24: SNOW | K24: 1 | L24: 44791 | M24: =DAY(L24) -> 18 | N24: =MONTH(L24) -> 8 | O24: =YEAR(L24) -> 2022 | R24: 620 | S24: =R24*1.09677 -> 679.9974 | T24: =ROUNDUP(S24*1.05,2) -> 714 | U24: =ROUNDUP(T24*1.05,2) -> 749.7 | V24: =U24*1.075 -> 805.9275 | W24: =6*V24 -> 4835.565 | Y24: EMITIDO BOLETOS JAN A JUN26 | AE24: EDUARDO COSTA GARCIA PEREZ
A25: MARCIA DE PINHO VIEIRA | B25: 172619014 | C25: 102.004.198-62 | D25: 11 9 9918-8301 | E25: AV. WASHINGTON LUÍS 1576 APTO 264 A | F25: SANTO AMARO | G25: SÃO PAULO | H25: 04662-902 | I25: marciapvieira@hotmail.com | J25: RALF | K25: 1 | L25: 44914 | M25: =DAY(L25) -> 19 | N25: =MONTH(L25) -> 12 | O25: =YEAR(L25) -> 2022 | R25: 1200 | S25: 1200 | T25: 630 | U25: =ROUNDUP(T25*1.05,2) -> 661.5 | V25: =U25*1.075 -> 711.1125 | W25: =6*V25 -> 4266.675 | Y25: EMITIDO BOLETOS JAN A JUN26 | AE25: MARCIA DE PINHO VIEIRA
A26: DIEGO CARNEIRO BARRETO | B26: 56614758 | C26: 057.140.166-02 | D26: 11 9 9294-4877 | E26: RUA DONA ANA HELENA DE SALLES GUSMÃO 206 | F26: JARDIM PAULISTANO | G26: SÃO PAULO | H26: 01457-040 | I26: diego.carneiro.barreto@gmail.com | J26: PIPOCA | K26: 1 | L26: 45004 | M26: =DAY(L26) -> 19 | N26: =MONTH(L26) -> 3 | O26: =YEAR(L26) -> 2023 | R26: 680 | S26: 680 | T26: =ROUNDUP(S26*1.05,2) -> 714 | U26: =ROUNDUP(T26*1.05,2) -> 749.7 | V26: =U26*1.075 -> 805.9275 | W26: =6*V26 -> 4835.565 | Y26: EMITIDO BOLETOS JAN A JUN26 | AE26: DIEGO CARNEIRO BARRETO
A27: LUIZ CARLOS GONÇALVES | B27: 6170605 - X | C27: 839.322.248-68 | D27: 11 9 8198 -0517 | E27: RUA ZACARIAS DE GOES 2006 | F27: CAMPO BELO | G27: SÃO PAULO | H27: 04610-005 | I27: luizgoncalves@joyeventos.com.br | J27: FIDEL | K27: 1 | L27: 45327 | M27: =DAY(L27) -> 5 | N27: =MONTH(L27) -> 2 | O27: =YEAR(L27) -> 2024 | T27: 680 | U27: =ROUNDUP(T27*1.05,2) -> 714 | V27: =U27*1.075 -> 767.55 | W27: =6*V27 -> 4605.3 | Y27: EMITIDO BOLETOS JAN A DEZ26 | AE27: LUIZ CARLOS GONÇALVES
A28: MARGARETH NODA | B28: 19994767 | C28: 117.705.128-10 | D28: 11 9 9825-5983 | E28: AVENIDA DOUTOR LUIZ ANTONIO PEDUTI CUNHA 180 CASA | F28: PARQUE DOS PRINCIPES | G28: SÃO PAULO | H28: 05396-270 | I28: margareth@cvm.gov.br | J28: SCHUMANN | K28: 1 | L28: 45367 | M28: =DAY(L28) -> 16 | N28: =MONTH(L28) -> 3 | O28: =YEAR(L28) -> 2024 | S28: 680 | T28: 680 | U28: =ROUNDUP(T28*1.05,2) -> 714 | V28: =U28*1.075 -> 767.55 | W28: =6*V28 -> 4605.3 | Y28: EMITIDO BOLETOS JAN A JUN26 | AE28: MARGARETH NODA
A29: MARIA ADALGISA RODRIGUES ARAUJO | B29: 16270809-9 | C29: 78327024787 | D29: 11 9 9623-9814 | E29: RUA DOUTOR ALFREDO DI VERNIE 104 | F29: BUTANTÃ | G29: SÃO PAULO | H29: 05540-020 | I29: gisaphilip@gmail.com | J29: PIPOCA | K29: 1 | L29: 45381 | M29: =DAY(L29) -> 30 | N29: =MONTH(L29) -> 3 | O29: =YEAR(L29) -> 2024 | S29: 680 | T29: 680 | U29: =ROUNDUP(T29*1.05,2) -> 714 | V29: =U29*1.075 -> 767.55 | W29: =6*V29 -> 4605.3 | Y29: EMITIDO BOLETOS DE JAN A JUN26 | AE29: MARIA ADALGISA RODRIGUES ARAUJO
A30: DESIREE MICHELLE CASTILHO NAPOLI | B30: 308477236 | C30: 31978563841 | D30: 11 99326-1999 | E30: RUA VINTE E OITO DE SETEMBRO 900 | F30: VILA DOM PEDRO I | G30: SÃO PAULO | H30: 04267-000 | I30: desiree.napoli@yahoo.com.br | J30: YUPIE | K30: 1 | L30: 45434 | M30: =DAY(L30) -> 22 | N30: =MONTH(L30) -> 5 | O30: =YEAR(L30) -> 2024 | S30: 680 | T30: 680 | U30: =ROUNDUP(T30*1.05,2) -> 714 | V30: =U30*1.075 -> 767.55 | W30: =6*V30 -> 4605.3 | Y30: EMITIDO BOLETOS DE JAN A JUN26 | AE30: DESIREE MICHELLE CASTILHO NAPOLI
A31: ANDRE ANDRADE | B31: 34539099 | C31: 328.166.618-30 | D31: 11 9 7120-6035 | E31: RUA CARVALHO DE FREITAS PROVENCE MORUMBI, 420 APTO 74 | F31: VILA ANDRADE | G31: SÃO PAULO | H31: 05728-030 | I31: andreandrade04@gmail.com | J31: CANÚ E LÉO | K31: 2 | L31: 45459 | M31: =DAY(L31) -> 16 | N31: =MONTH(L31) -> 6 | O31: =YEAR(L31) -> 2024 | S31: 1250 | T31: 1250 | U31: =ROUNDUP(T31*1.05,2) -> 1312.5 | V31: =U31*1.075 -> 1410.9375 | W31: =6*V31 -> 8465.625 | Y31: EMITIDO BOLETOS JAN A JUN26 | AE31: ANDRE ANDRADE
A32: NEY FERREIRA DE SOUZA GUERRA | B32: 306529014 | C32: 295675548-03 | D32: 11 9 9384-5291 | E32: RUA ALVES GUIMARÃES 911 APTO 82 | F32: PINHEIROS | G32: SÃO PAULO | H32: 05410-001 | I32: nguerra229@gmail.com | J32: BOAZ E LIA | K32: 2 | L32: 45533 | M32: =DAY(L32) -> 29 | N32: =MONTH(L32) -> 8 | O32: =YEAR(L32) -> 2024 | P32: 1740 | Q32: 1740 | R32: 1926.4288 | S32: 1408.57 | T32: =ROUNDUP(S32*1.05,2) -> 1479 | U32: =ROUNDUP(T32*1.05,2) -> 1552.95 | V32: =U32*1.075 -> 1669.4212 | W32: =6*V32 -> 10016.528 | Y32: EMITIDO BOLETOS DE JAN A JUN26 | Z32: ='Ex residentes'!Y329+714 -> 46823 | AE32: NEY FERREIRA DE SOUZA GUERRA
A33: MARINA HARUKO MORI BIONDO | B33: 261831173 | C33: 310211708-28 | D33: 1199801-9800 | E33: AVENIDA SENADOR CASEMIRO DA ROCHA 809 APTO 162 | F33: MIRANDOPOLIS | G33: SÃO PAULO | H33: 40470-02 | I33: marinahmori@gmail.com | J33: VITO | K33: 1 | L33: 45582 | M33: =DAY(L33) -> 17 | N33: =MONTH(L33) -> 10 | O33: =YEAR(L33) -> 2024 | T33: 680 | U33: =ROUNDUP(T33*1.05,2) -> 714 | V33: =U33*1.075 -> 767.55 | W33: =6*V33 -> 4605.3 | Y33: EMITIDO BOLETOS JAN A JUN26
A34: CARLA VIANA CHARVES DA SILVA | B34: 43421281 | C34: 33940435805 | D34: 11 91714-3677 | E34: RUA MASATO SAKAI 180 BURITIS 7 APTO 44 | F34: JARDIM SÃO MIGUEL | G34: FERRAZ DE VASCONCELOS | H34: 08538-300 | I34: carlaviana304@gmail.com | J34: PUPY | K34: 1 | L34: 45643 | M34: =DAY(L34) -> 17 | N34: =MONTH(L34) -> 12 | O34: =YEAR(L34) -> 2024 | T34: 680 | U34: =ROUNDUP(T34*1.05,2) -> 714 | V34: =U34*1.075 -> 767.55 | W34: =6*V34 -> 4605.3 | Y34: EMITIDO BOLETOS JAN A JUN26
A35: RITA MARIELLA MALTESE DIAZ DE BRAVO | B35: RNMF5682262 | C35: 717.567.491-08 | D35: 51967790103 | E35: RUA BARÃO DE RAMALHO 413 | F35: UVARANAS | G35: PONTA GROSSA | H35: 84030-100 | I35: rmmaltese@gmail.com | J35: NEGÃO | K35: 1 | L35: 45647 | M35: =DAY(L35) -> 21 | N35: =MONTH(L35) -> 12 | O35: =YEAR(L35) -> 2024 | P35: =DAY(O35) -> 16 | Q35: =MONTH(O35) -> 7 | R35: =YEAR(O35) -> 1905 | S35: =DAY(R35) -> 19 | T35: 680 | U35: =ROUNDUP(T35*1.05,2) -> 714 | V35: =U35*1.075 -> 767.55 | W35: =6*V35 -> 4605.3 | Y35: EMITIDO BOLETOS DE JAN A JUN26
A36: ELIANA DE FREITAS PUGLESI LOMES | B36: 44966523 | C36: 365.106.468-97 | D36: 11 9 8655-4554 | E36: RUA CORONEL JOSE DIONISIO GOUVEIA 29 | F36: VILA CLEMENTINO | G36: SÃO PAULO | H36: 04026-060 | I36: eliana.puglesi@gmail.com | J36: BRENDA | K36: 1 | L36: 45653 | M36: =DAY(L36) -> 27 | N36: =MONTH(L36) -> 12 | O36: =YEAR(L36) -> 2024 | T36: 680 | U36: =ROUNDUP(T36*1.05,2) -> 714 | V36: =U36*1.075 -> 767.55 | W36: =6*V36 -> 4605.3 | Y36: EMITIDO BOLETOS DE JAN A JUN26
A37: GABRIELA LONGHI GARGANTINI | B37: 554163767 | C37: 445.536.158-86 | D37: 11 9 47378507 | E37: RUA MARECHAL BADOGLIO, 256 | F37: VILA MUSSOLINI | G37: SÃO BERNARDO DO CAMPO | H37: 09620-020 | I37: gabi.gargantini@gmail.com | J37: BARNEY, NEGO E TAYLA | K37: 3 | L37: 45667 | M37: =DAY(L37) -> 10 | N37: =MONTH(L37) -> 1 | O37: =YEAR(L37) -> 2025 | U37: 2040 | V37: =U37*1.075 -> 2193 | W37: =6*V37 -> 13158 | Y37: EMITIDO BOLETOS JAN A DEZ26
A38: DENISE RIBOLI FAUSTINO | B38: 47618232-3 | C38: 354.035.708-45 | D38: 1146198490 | E38: PRAÇA OIAPOQUE 360 APTO 1603 AN 16 | F38: ALPHAVILLE INDUSTRIAL | G38: BARUERI | H38: 06454-060 | I38: denise@tecnotrat.com.br | J38: LEIA E LUKE | K38: 2 | L38: 45701 | M38: =DAY(L38) -> 13 | N38: =MONTH(L38) -> 2 | O38: =YEAR(L38) -> 2025 | U38: 1428 | V38: =U38*1.075 -> 1535.1 | W38: =6*V38 -> 9210.6 | Y38: EMITIDO BOLETOS JAN A JUN26
A39: RENATA MARIA TEIXEIRA PINHEIRO | B39: 284291201 | C39: 311.747.488-93 | D39: 11 998005503 | E39: RUA ALVES GUIMARAES, 661 CS | F39: PINHEIROS | G39: SÃO PAULO | H39: 05410-001 | I39: renata.pinheiro@uol.com.br | J39: AYLA | K39: 1 | L39: 45727 | M39: =DAY(L39) -> 11 | N39: =MONTH(L39) -> 3 | O39: =YEAR(L39) -> 2025 | U39: 714 | V39: =U39*1.075 -> 767.55 | W39: =6*V39 -> 4605.3 | Y39: EMITIDO BOLETOS JAN A JUN26
A40: ROBERT DE MACEDO SOARES RITTSCHER | B40: 9785232 | C40: 080.574.348-05 | D40: 11 9 9135-0202 | E40: RUA JOAO MOURA 502 APTO 153 | F40: PINHEIROS | G40: SÃO PAULO | H40: 05412-001 | I40: robertrittscher@gmail.com | J40: ZECA | K40: 1 | L40: 45788 | M40: =DAY(L40) -> 11 | N40: =MONTH(L40) -> 5 | O40: =YEAR(L40) -> 2025 | T40: 714 | U40: 714 | V40: =U40*1.075 -> 767.55 | W40: =6*V40 -> 4605.3 | Y40: EMITIDO BOLETOS JAN A JUN26
...

Sheet Ex residentes
A1: Nome | B1: RG | C1: CPF | D1: Telefone | E1: Endereço | F1: Bairro | G1: Cidade | H1: Cep | I1: Email | J1: Nome do cão | K1: QDE DE CÃES | L1: Data de pagamento | M1: Dia | N1: Mês | O1: Ano | P1: Valor | Q1: Valor1 | R1: Valor2 | S1: X | T1: DDA | U1: obs1 | V1: obs2 | W1: obs3 | X1: obs4 | Y1: DATA DE SAIDA | Z1: Dia Saida | AA1: Mês Saida | AB1: Ano Saída
A2: GABRIELLE HEIN COCA | B2: 44.199.121-X | C2: 337582838-17 | D2: 11 3063-4852 | E2: ESTRADA DOS INDIOS, 342 | F2: ARUJAZINHO 04 | G2: ARUJA | H2: 07400-000 | I2: gabrielle_hein@yahoo.com.br | J2: JACK | K2: 1 | L2: 40690 | M2: =DAY(L2) -> 27 | N2: =MONTH(L2) -> 5 | O2: =YEAR(L2) -> 2011 | P2: 425 | Q2: Emitido boleto Jul a dez_12 | R2: =P2*6 -> 2550 | Z2: =IF($Y2=0,"",DAY($Y2)) | AA2: =IF($Y2=0,"",MONTH($Y2)) | AB2: =IF($Y2=0,"",YEAR($Y2))
A3: ANA HELENA DE CAMPOS | B3: 16474292 | C3: 206085958-10 | D3: 11 2609-1545 | E3: RUA CORINTO n° 199 APTO 181 M | F3: VILA INDIANA | G3: SÃO PAULO | H3: 05586-060 | I3: decamposah@gmail.com | J3: TRUPPY | K3: 1 | L3: 41080 | M3: =DAY(L3) -> 20 | N3: =MONTH(L3) -> 6 | O3: =YEAR(L3) -> 2012 | P3: 450 | Q3: Emitido boleto Jul a dez_12 | R3: =P3*6 -> 2700 | Z3: =IF($Y3=0,"",DAY($Y3)) | AA3: =IF($Y3=0,"",MONTH($Y3)) | AB3: =IF($Y3=0,"",YEAR($Y3))
A4: ANA CRISTINA COLLOR | B4: 228021996 | C4: 142372768-13 | D4: 21 2146-4182 | E4: AVENIDA PREFEITO DUCIDIO CARDOSO N°1100 BLC. II - APTº 403 | F4: BARRA DA TIJUCA | G4: Rio de Janeiro | H4: 22620-311 | I4: anapetrone@uol.com.br | J4: HANNA | K4: 1 | L4: 41004 | M4: =DAY(L4) -> 5 | N4: =MONTH(L4) -> 4 | O4: =YEAR(L4) -> 2012 | P4: 695 | R4: =P4*6 -> 4170 | Z4: =IF($Y4=0,"",DAY($Y4)) | AA4: =IF($Y4=0,"",MONTH($Y4)) | AB4: =IF($Y4=0,"",YEAR($Y4))
A5: CRISTINA FERNANDEZ VARELA | B5: 20473710-2 | C5: 194.410.098-90 | D5: 11 99449-3739 | E5: RUA SANTO ANDRÉ N° 430 APTO 54 | F5: VILA ASSUNÇÃO | G5: Santo André | H5: 09020-230 | I5: cristina.varela@ge.com | J5: DEXTER | K5: 1 | L5: 41503 | M5: 17 | N5: 8 | O5: 2013 | P5: 425 | Q5: =ROUNDUP((P5*1.1294),2) -> 480 | R5: =Q5*6 -> 2880 | T5: DDA | U5: EMITIDO JUL A DEZ 14 | Z5: =IF($Y5=0,"",DAY($Y5)) | AA5: =IF($Y5=0,"",MONTH($Y5)) | AB5: =IF($Y5=0,"",YEAR($Y5))
A6: TOMI SAITO | B6: 355986255 | C6: 230974978-89 | D6: 11 4443-1900 | E6: RUA CAPIVARINHAS N° 54 | F6: ALTO DE PINHEIROS | G6: São Paulo | H6: 05458-010 | I6: tomiakio@gmail.com | J6: TOBI | K6: 1 | L6: 40488 | M6: =DAY(L6) -> 6 | N6: =MONTH(L6) -> 11 | O6: =YEAR(L6) -> 2010 | P6: 425 | Q6: =ROUNDUP((P6*1.1294),2) -> 480 | R6: 2101.5 | T6: DDA | U6: EMITIDO JUL A SET 14 | Z6: =IF($Y6=0,"",DAY($Y6)) | AA6: =IF($Y6=0,"",MONTH($Y6)) | AB6: =IF($Y6=0,"",YEAR($Y6))
A7: MARIA CRISTINA HOLTMANN | B7: 17141448 | C7: 305666628-76 | D7: 11 3288-1500 | E7: RUA DR° BRASILIO MACHADO, 218 - APTO 152 | F7: SANTA CECILIA | G7: São Paulo | H7: 01230-010 | I7: cris.pastore@yahoo.com.br | J7: TAIO | K7: 1 | L7: 40492 | M7: =DAY(L7) -> 10 | N7: =MONTH(L7) -> 11 | O7: =YEAR(L7) -> 2010 | P7: 425 | Q7: =ROUNDUP((P7*1.1294),2) -> 480 | R7: =Q7*6 -> 2880 | U7: EMITIDO JUL A DEZ 14 | Z7: =IF($Y7=0,"",DAY($Y7)) | AA7: =IF($Y7=0,"",MONTH($Y7)) | AB7: =IF($Y7=0,"",YEAR($Y7))
A8: EDUARDO ARANTES BARCELLOS | B8: 51547922 | C8: 94316066820 | D8: 11 3807-5611 | E8: AL TALIA, 37 CONDOMINIO JARDIM IOLANDA | F8: TABOÃO DA SERRA | G8: São Paulo | H8: 6794090 | I8: edubarcellos@uol.com.br | J8: LUNA | K8: 1 | L8: 41900 | M8: 18 | N8: 9 | O8: 2014 | P8: 480 | Q8: 654 | R8: =Q8*3 -> 1962 | U8: EMITIDO OUT A DEZ 14 | Z8: =IF($Y8=0,"",DAY($Y8)) | AA8: =IF($Y8=0,"",MONTH($Y8)) | AB8: =IF($Y8=0,"",YEAR($Y8))
A9: FERNANDA CAROLINA HILARIO DE CAMPOS | B9: 30769370-3 | C9: 329474088-37 | D9: 11 2364-9105 | E9: RUA PADRE JOAO GUALBERTO N°581 APTO 15 A | F9: IMIRIM | G9: São Paulo | H9: 02537-000 | I9: fernanda.carolina@hotmail.com | J9: PRETA | K9: 1 | L9: 40500 | M9: =DAY(L9) -> 18 | N9: =MONTH(L9) -> 11 | O9: =YEAR(L9) -> 2010 | P9: 390 | Q9: 480 | R9: =Q9*6 -> 2880 | U9: EMITIDO JUL A DEZ 14 | Z9: =IF($Y9=0,"",DAY($Y9)) | AA9: =IF($Y9=0,"",MONTH($Y9)) | AB9: =IF($Y9=0,"",YEAR($Y9))
A10: GLADSTONE DE JESUS CARDOSO | B10: M1477793 | C10: 371952556-20 | D10: 11 4362-5491 | E10: Av. Senador Vergueiro Nº 1320 APTO 02 | F10: JARDIM TRES MARIAS | G10: São Bernardo do Campo | H10: 09750-001 | I10: miguel.rc@bol.com.br | J10: JUNINHO | K10: 1 | L10: 40951 | M10: =DAY(L10) -> 12 | N10: =MONTH(L10) -> 2 | O10: =YEAR(L10) -> 2012 | P10: 480 | Q10: 542.12 | R10: =Q10*6 -> 3252.72 | U10: EMITIDO JUL A DEZ 14 | Z10: =IF($Y10=0,"",DAY($Y10)) | AA10: =IF($Y10=0,"",MONTH($Y10)) | AB10: =IF($Y10=0,"",YEAR($Y10))
A11: PAULO RENATO BATISTA ALEXANDRE | B11: 05516900-7 | C11: 83653740720 | D11: 52 777-1109129 | E11: AVENIDA . JANDIRA, 79 BLC A APTO 24 | F11: MOEMA | G11: São Paulo | H11: 04080-007 | I11: paulorenatoba@yahoo.com | J11: CONCA E BILLY | K11: 2 | L11: 41861 | M11: 10 | N11: 8 | O11: 2014 | P11: 912 | Q11: =P11 -> 912 | R11: =Q11*6 -> 5472 | Z11: =IF($Y11=0,"",DAY($Y11)) | AA11: =IF($Y11=0,"",MONTH($Y11)) | AB11: =IF($Y11=0,"",YEAR($Y11))
A12: JOÃO BATISTA SANTANA | B12: 4.136.945-22 | C12: 194222968-20 | D12: 11-5562-4254 | E12: RUA CONTOS GAUCHESCOS 251 | F12: VILA STA. CATARINA | G12: São Paulo | H12: 04369-000 | I12: jotabe.santana@uol.com.br | J12: BELLA | K12: 1 | L12: 41933 | M12: 21 | N12: 10 | O12: 2014 | P12: 480 | Q12: =P12 -> 480 | R12: =Q12*6 -> 2880 | Z12: =IF($Y12=0,"",DAY($Y12)) | AA12: =IF($Y12=0,"",MONTH($Y12)) | AB12: =IF($Y12=0,"",YEAR($Y12))
A13: LUCAS FERNANDES DIAS | B13: 13270736 | C13: 082.284.866-00 | D13: 11-98663-4661 | E13: RUA AUGUSTA 554 APTO 41 | F13: CONSOLAÇÃO | G13: São Paulo | H13: 1304000 | I13: dsinerlucas@hotmail.com | J13: JUANNA | K13: 1 | L13: 23/1014 | M13: 23 | N13: 10 | O13: 2014 | P13: 480 | Q13: =P13 -> 480 | R13: =Q13*6 -> 2880 | Z13: =IF($Y13=0,"",DAY($Y13)) | AA13: =IF($Y13=0,"",MONTH($Y13)) | AB13: =IF($Y13=0,"",YEAR($Y13))
A14: CRISTIANE DE SANTANA MONTEIRO | B14: 21976363 | C14: 129154208-66 | D14: 11-97330-6120 | E14: AV. MARQUES DE SAO VICENTE 2914 APTO 144 A | F14: BARRA FUNDA | G14: São Paulo | H14: 5036040 | I14: csmonteiro@ig.com.br | J14: NINA | K14: 1 | L14: 41884 | M14: 2 | N14: 9 | O14: 2014 | P14: 480 | Q14: =P14 -> 480 | R14: =Q14*6 -> 2880 | U14: EMITIDO JAN A JUN 2015 | Z14: =IF($Y14=0,"",DAY($Y14)) | AA14: =IF($Y14=0,"",MONTH($Y14)) | AB14: =IF($Y14=0,"",YEAR($Y14))
A15: FERNANDA LOPES VONKUTZLEBEN | B15: 44046182-0 | C15: 339251428-43 | D15: 11 8912-5128 | E15: RUA PROFESSOR ARTHUR RAMOS N°204 APTO 101 | F15: JARDIM PAULISTANO | G15: São Paulo | H15: 01454-010 | I15: FERNANDAVON@HOTMAIL.COM | J15: THAI | K15: 1 | L15: 40047 | M15: =DAY(L15) -> 22 | N15: =MONTH(L15) -> 8 | O15: =YEAR(L15) -> 2009 | P15: 590 | Q15: =ROUNDUP((P15*1.1294),2) -> 666.35 | R15: =Q15*6 -> 3998.1 | Z15: =IF($Y15=0,"",DAY($Y15)) | AA15: =IF($Y15=0,"",MONTH($Y15)) | AB15: =IF($Y15=0,"",YEAR($Y15))
A16: ALEXANDRINA TOMAZINI TEIXEIRA DOS SANTOS | B16: 5327039 | C16: 063.790.858-90 | D16: 11 3971-8617 | E16: Rua SANTO AMARO 766 APTO 154 A | F16: BELA VISTA | G16: São Paulo | H16: 01315-000 | I16: alexsp74@hotmail.com | J16: SOPHIA | K16: 1 | L16: 41836 | M16: 16 | N16: 7 | O16: 2014 | P16: 480 | Q16: =P16 -> 480 | R16: =Q16*6 -> 2880 | U16: EMITIDO JAN A JUN 15 | Z16: =IF($Y16=0,"",DAY($Y16)) | AA16: =IF($Y16=0,"",MONTH($Y16)) | AB16: =IF($Y16=0,"",YEAR($Y16))
A17: AMANDA KUHLMANN DE MELLO ANGERAMI | B17: 29.763.214-6 | C17: 351976598-58 | D17: 11 5083-1458 | E17: RUA JORGE TIBIRIÇA, 159 APTO 63 | F17: VILA MARIANA | G17: São Paulo | H17: 4126000 | I17: amandakangerami@gmail.com | J17: MEL E CHE GUEVARA | K17: 2 | L17: 41838 | M17: 18 | N17: 7 | O17: 2014 | P17: 912 | Q17: =P17 -> 912 | R17: =Q17*6 -> 5472 | Z17: =IF($Y17=0,"",DAY($Y17)) | AA17: =IF($Y17=0,"",MONTH($Y17)) | AB17: =IF($Y17=0,"",YEAR($Y17))
A18: MIREIA VILA GARCIA | B18: 34425320-X | C18: 220156098-65 | D18: 11 5055-3402 | E18: ALAMEDA DOS ARAPANES n° 1084 apto 182 | F18: MOEMA | G18: São Paulo | H18: 04524-001 | I18: mireia.vilagarcia@gmail.com | J18: AGATHA | K18: 1 | L18: 40815 | M18: =DAY(L18) -> 29 | N18: =MONTH(L18) -> 9 | O18: =YEAR(L18) -> 2011 | P18: 425 | Q18: 380 | R18: =Q18*6 -> 2280 | U18: EMITIDO JAN A JUN 2015 | Z18: =IF($Y18=0,"",DAY($Y18)) | AA18: =IF($Y18=0,"",MONTH($Y18)) | AB18: =IF($Y18=0,"",YEAR($Y18))
A19: RODRIGO SERVIO VERGARA | B19: 19404112-8 | C19: 138735788-32 | D19: 11-996395266 | E19: RUA SÃO BENTO, 2583 JARDIM PRIMAVERA | F19: JARDIM PRIMAVERA | G19: SÃO PAULO | I19: rodrigosvergara@gmail.com | J19: VOS E CHE | K19: 2 | L19: 42063 | M19: 28 | N19: 2 | O19: 2015 | P19: 3600 | Q19: 900 | R19: 900 | Z19: =IF($Y19=0,"",DAY($Y19)) | AA19: =IF($Y19=0,"",MONTH($Y19)) | AB19: =IF($Y19=0,"",YEAR($Y19))
A20: ANGELINA DE OLIVEIRA SOUZA | B20: 4370568972 | C20: 326214328-67 | D20: 11 3774-6239 | E20: RUA PEDRO DOLL N°269 APTO 32 | F20: SANTANA | G20: São Paulo | H20: 02404-000 | I20: geldeoliveira@hotmail.com | J20: FRED | K20: 1 | L20: 40995 | M20: =DAY(L20) -> 27 | N20: =MONTH(L20) -> 3 | O20: =YEAR(L20) -> 2012 | P20: 425 | Q20: =ROUNDUP((P20*1.1294),2) -> 480 | R20: =Q20*6 -> 2880 | Z20: =IF($Y20=0,"",DAY($Y20)) | AA20: =IF($Y20=0,"",MONTH($Y20)) | AB20: =IF($Y20=0,"",YEAR($Y20))
A21: MARINA SOARES PORFIRIO DE SOUZA | B21: 81151792 | C21: 996872168-91 | D21: 11 2619-1459 | E21: AVENIDA NOVA CANTAREIRA n° 1076 APTO 114 | F21: TUCURUVI | G21: São Paulo | H21: 02330-001 | I21: marinaspsouza@hotmail.com | J21: SPIKE | K21: 1 | L21: 40551 | M21: =DAY(L21) -> 8 | N21: =MONTH(L21) -> 1 | O21: =YEAR(L21) -> 2011 | P21: 415 | Q21: =ROUNDUP((P21*1.1294),2) -> 468.71 | R21: =Q21*6 -> 2812.26 | U21: EMITIDO DE JULHO A DEZ15 | Z21: =IF($Y21=0,"",DAY($Y21)) | AA21: =IF($Y21=0,"",MONTH($Y21)) | AB21: =IF($Y21=0,"",YEAR($Y21))
A22: MARIA FERNANDA RIGO CAVINATO | B22: 25943880-7 | C22: 368990678-46 | D22: 11 999887550 | E22: RUA TIRADENTES, 95 APTO 33 | F22: CENTRO | G22: SÃO BERNARDO DO CAMPO | H22: 09780-000 | I22: mfrcavinato@gmail.com | J22: ZUKE | K22: 1 | L22: 41878 | M22: =DAY(L22) -> 27 | N22: =MONTH(L22) -> 8 | O22: =YEAR(L22) -> 2014 | P22: 550 | Q22: =P22 -> 550 | R22: =Q22*6 -> 3300 | U22: EMITIDO DE JULHO A DEZ15 | Z22: =IF($Y22=0,"",DAY($Y22)) | AA22: =IF($Y22=0,"",MONTH($Y22)) | AB22: =IF($Y22=0,"",YEAR($Y22))
A23: CAMILA MOYA ALBERA DA COSTA | B23: 305433945 | C23: 326189408-30 | D23: 11 5521-6564 | E23: RUA VERGUEIRO 8993 BLC 2 APTO 14 | F23: ? | G23: São Paulo | H23: 4273200 | I23: camilamoya@picture.com.br | J23: NENE | K23: 1 | L23: 41860 | M23: =DAY(L23) -> 9 | N23: =MONTH(L23) -> 8 | O23: =YEAR(L23) -> 2014 | P23: 480 | Q23: =P23 -> 480 | R23: =Q23*6 -> 2880 | T23: DDA | U23: EMITIDO DE JULHO A DEZ15 | Z23: =IF($Y23=0,"",DAY($Y23)) | AA23: =IF($Y23=0,"",MONTH($Y23)) | AB23: =IF($Y23=0,"",YEAR($Y23))
A24: PAULA MATHIAS GOMES | B24: 277595277 | C24: 222644058-56 | D24: 11 2369-5248 | E24: RUA COPACABANA N°406 APTO 92 | F24: SANTA TEREZINHA | G24: São Paulo | H24: 02461-000 | I24: mathiaspaula9540@hotmail.com | J24: BUSTER | K24: 1 | L24: 40927 | M24: =DAY(L24) -> 19 | N24: =MONTH(L24) -> 1 | O24: =YEAR(L24) -> 2012 | P24: 390 | Q24: 480 | R24: =Q24*6 -> 2880 | U24: EMITIDO DE JULHO A DEZ15 | Z24: =IF($Y24=0,"",DAY($Y24)) | AA24: =IF($Y24=0,"",MONTH($Y24)) | AB24: =IF($Y24=0,"",YEAR($Y24))
A25: JAYME FERNANDEZ | B25: 300910010 | C25: 253550098-16 | D25: 11-999620702 | E25: RUA CAMILO NADER 123 APTO 81 | F25: VILA MORUMBI | G25: São Paulo | H25: 05688-031 | I25: recopelli@hotmail.com | J25: TONHO | K25: 1 | L25: 41683 | M25: =DAY(L25) -> 13 | N25: =MONTH(L25) -> 2 | O25: =YEAR(L25) -> 2014 | P25: 480 | Q25: 480 | R25: =Q25*6 -> 2880 | U25: EMITIDO DE JULHO A DEZ15 | Z25: =IF($Y25=0,"",DAY($Y25)) | AA25: =IF($Y25=0,"",MONTH($Y25)) | AB25: =IF($Y25=0,"",YEAR($Y25))
A26: PAULO RENATO BATISTA ALEXANDRE | B26: 05516900-7 | C26: 836537407-20 | D26: 11 2769-3572 | E26: AV. JANDIRA, 79 BLOCÃO A APTO 24 | F26: MOEMA | G26: São Paulo | H26: 04080-007 | I26: paulorenatoba@yahoo.com | J26: BILLY | K26: 1 | L26: 42183 | M26: 28 | N26: 6 | O26: 2015 | P26: 480 | Q26: 480 | R26: =Q26*3 -> 1440 | U26: EMITIDO DE JULHO A SET15 | Z26: =IF($Y26=0,"",DAY($Y26)) | AA26: =IF($Y26=0,"",MONTH($Y26)) | AB26: =IF($Y26=0,"",YEAR($Y26))
A27: OTAVIO VILLARES DE FREITAS | B27: 13737201 | C27: 126400238-61 | D27: 11 99982-7221 | E27: RUA DR. PINTO FERRAZ, 49 AP 116 | F27: VILA MARIANA | G27: SÃO PAULO | H27: 04117-040 | I27: OTAVIOVF@GMAIL.COM | J27: NED | K27: 1 | L27: 42271 | M27: 28 | N27: 6 | O27: 2015 | P27: 400 | Q27: 1200 | U27: PAGO POR 3 MESES SET, OUT E NOV | Z27: =IF($Y27=0,"",DAY($Y27)) | AA27: =IF($Y27=0,"",MONTH($Y27)) | AB27: =IF($Y27=0,"",YEAR($Y27))
A28: ANA CLAUDIA CUNHA TRAVASSOS | B28: 141308254 | C28: 245768928-78 | D28: 11-982446128 | E28: AV. GUILHERME DUMONT VILLARES, 2001 APTO 13 | F28: JD LONDRINA | G28: SÃO PAULO | H28: 05640-003 | I28: acctravassos@gmail.com | J28: NICK E MEL | K28: 2 | L28: 42010 | M28: =DAY(L28) -> 6 | N28: =MONTH(L28) -> 1 | O28: =YEAR(L28) -> 2015 | P28: 912 | Q28: 912 | R28: =Q28*6 -> 5472 | U28: EMITIDO DE JAN A JUN16 | Z28: =IF($Y28=0,"",DAY($Y28)) | AA28: =IF($Y28=0,"",MONTH($Y28)) | AB28: =IF($Y28=0,"",YEAR($Y28))
A29: DANIEL HABERER | B29: W368408 | C29: 251289448-75 | D29: 11 98122-8818 | E29: RUA IBIAPINOPOLIS, 947 APTO 91 | F29: JARDIM PAULISTANO | G29: São Paulo | H29: 01457-030 | I29: daniel@cosmotrade.com.br | J29: SANNY | K29: 1 | L29: 41866 | M29: =DAY(L29) -> 15 | N29: =MONTH(L29) -> 8 | O29: =YEAR(L29) -> 2014 | P29: 480 | Q29: 480 | R29: =Q29*6 -> 2880 | U29: EMITIDO DE JAN A JUN16 | Z29: =IF($Y29=0,"",DAY($Y29)) | AA29: =IF($Y29=0,"",MONTH($Y29)) | AB29: =IF($Y29=0,"",YEAR($Y29))
A30: EDNA MARIA COSTA BEDINI | B30: 9.738.994-8 | C30: 770578138-72 | D30: 11 2642-2261 | E30: RUA DOUTOR VICENTE GIACAGLINI, 556 TORRE 1 APTO 22 | F30: VILA BELA | G30: SÃO PAULO | H30: 03203-000 | I30: ednabedini@gmail.com | J30: PANDORA | K30: 1 | L30: 42266 | M30: =DAY(L30) -> 19 | N30: =MONTH(L30) -> 9 | O30: =YEAR(L30) -> 2015 | Q30: 480 | R30: =Q30*6 -> 2880 | U30: EMITIDO DE JAN A JUN16 | Z30: =IF($Y30=0,"",DAY($Y30)) | AA30: =IF($Y30=0,"",MONTH($Y30)) | AB30: =IF($Y30=0,"",YEAR($Y30))
A31: CHRISTIAN MESQUITA YEGH | B31: 34361179 | C31: 292738368-52 | D31: 11 9 4727-2910 | E31: RUA NOSSA SENHORA DA SAÚDE, 287 APTO 68 BLC II | F31: VILA SANTO ESTEFANO | G31: SÃO PAULO | H31: 04159-000 | I31: christianyegh@gmail.com | J31: DONATELLA | K31: 1 | L31: 42225 | M31: =DAY(L31) -> 9 | N31: =MONTH(L31) -> 8 | O31: =YEAR(L31) -> 2015 | P31: 480 | Q31: 480 | R31: =Q31*6 -> 2880 | U31: EMITIDO DE JAN A JUN16 | Z31: =IF($Y31=0,"",DAY($Y31)) | AA31: =IF($Y31=0,"",MONTH($Y31)) | AB31: =IF($Y31=0,"",YEAR($Y31))
A32: ELIZA MARA CRISTINO COSTA | B32: 8229130 | C32: 032.179.018-94 | D32: 11 28180392 | E32: RUA TONELEIROS, 346 APTO 91 | F32: VILA IPOJUCA | G32: SÃO PAULO | H32: 05056-000 | I32: elizasp2008@hotmail.com | J32: AISHA | K32: 1 | L32: 42392 | M32: =DAY(L32) -> 23 | N32: =MONTH(L32) -> 1 | O32: =YEAR(L32) -> 2016 | Q32: 420 | R32: =Q32*5 -> 2100 | U32: EMITIDO DE FEV A JUN16 | Z32: =IF($Y32=0,"",DAY($Y32)) | AA32: =IF($Y32=0,"",MONTH($Y32)) | AB32: =IF($Y32=0,"",YEAR($Y32))
A33: RUTHY DEBORA SASSOON | B33: 9894547-6 | C33: 49663378-36 | D33: 11 3666-2982 | E33: AVENIDA HIGIENOPOLIS, 1048 APTO 76 | F33: HIGIENOPOLIS | G33: SÃO PAULO | H33: 01238-000 | I33: ruthysassoon@bol.com.br | J33: ROCKY CROC | K33: 1 | L33: 42264 | M33: =DAY(L33) -> 17 | N33: =MONTH(L33) -> 9 | O33: =YEAR(L33) -> 2015 | Q33: 400 | R33: =Q33*6 -> 2400 | U33: EMITIDO BOLETO FEV16 | Z33: =IF($Y33=0,"",DAY($Y33)) | AA33: =IF($Y33=0,"",MONTH($Y33)) | AB33: =IF($Y33=0,"",YEAR($Y33))
A34: RENAN DE BRITO VIANA | B34: 302112455 | C34: 351.050.918-84 | D34: 11 37218070 | E34: RUA DOS TRES IRMÃOS 149 APTO 91 | F34: VILA PROGREDIDOR | G34: SÃO PAULO | H34: 05615-190 | I34: renanviana.pt@gmail.com | J34: MADALENA | K34: 1 | L34: 42390 | M34: =DAY(L34) -> 21 | N34: =MONTH(L34) -> 1 | O34: =YEAR(L34) -> 2016 | Q34: 480 | R34: =Q34*5 -> 2400 | Z34: =IF($Y34=0,"",DAY($Y34)) | AA34: =IF($Y34=0,"",MONTH($Y34)) | AB34: =IF($Y34=0,"",YEAR($Y34))
A35: ALCINDO HEBLING JUNIOR | B35: 17016885 | C35: 073356968-44 | D35: 11 5183-3654 | E35: RUA ALEXANDRE DUMAS N°1410, APTO 42 | F35: CHACARA SANTO ANTONIO | G35: São Paulo | H35: 04717-003 | I35: rhebling@me.com | J35: LUNA | K35: 1 | L35: 41178 | M35: =DAY(L35) -> 26 | N35: =MONTH(L35) -> 9 | O35: =YEAR(L35) -> 2012 | P35: 1026 | Q35: 400 | R35: =Q35*6 -> 2400 | U35: EMITIDO DE JAN A JUN16 | Z35: =IF($Y35=0,"",DAY($Y35)) | AA35: =IF($Y35=0,"",MONTH($Y35)) | AB35: =IF($Y35=0,"",YEAR($Y35))
A36: ALEX TAVARES FAIOTTO | B36: 364214041 | C36: 396.550.868-79 | D36: 11 29050159 | E36: RUA DOUTOR LUIZ MIGLIANO 761 APTO 184 A | F36: JARDIM CABORE | G36: SÃO PAULO | H36: 05711-001 | J36: GORDUCHA | K36: 1 | L36: 42395 | M36: =DAY(L36) -> 26 | N36: =MONTH(L36) -> 1 | O36: =YEAR(L36) -> 2016 | Q36: 480 | R36: =Q36*5 -> 2400 | U36: EMITIDO DE FEV A JUN16 | Z36: =IF($Y36=0,"",DAY($Y36)) | AA36: =IF($Y36=0,"",MONTH($Y36)) | AB36: =IF($Y36=0,"",YEAR($Y36))
A37: LUIZ FRANCISCO TORQUATO AVOLIO | B37: 6329430 | C37: 023116948-55 | D37: 11 3063-4627 | E37: ALAMEDA CASA BRANCA, 978 APTO 151 | F37: CERQUEIRA CESAR | G37: São Paulo | H37: 1408000 | I37: lfavolio@uol.com.br | J37: CHICO | K37: 1 | L37: 41896 | M37: =DAY(L37) -> 14 | N37: =MONTH(L37) -> 9 | O37: =YEAR(L37) -> 2014 | P37: 480 | Q37: =P37 -> 480 | R37: =Q37*6 -> 2880 | T37: DDA | U37: EMITIDO DE JAN A JUN16 | Z37: =IF($Y37=0,"",DAY($Y37)) | AA37: =IF($Y37=0,"",MONTH($Y37)) | AB37: =IF($Y37=0,"",YEAR($Y37))
A38: RENATA DE CARVALHO PINTO BUENO | B38: 254129997 | C38: 282496648-33 | D38: 11 33617185 | E38: RUA CAJUEIRO, 57 | F38: SAUSALITO | G38: MAIRIPORÃ | H38: 07600-000 | I38: renata@gaiolaestudio.com.br | J38: AZUL E RAICA | K38: 2 | L38: 42077 | M38: =DAY(L38) -> 14 | N38: =MONTH(L38) -> 3 | O38: =YEAR(L38) -> 2015 | P38: 912 | Q38: =P38 -> 912 | R38: =Q38*6 -> 5472 | U38: EMITIDO DE JAN A JUN16 | Z38: =IF($Y38=0,"",DAY($Y38)) | AA38: =IF($Y38=0,"",MONTH($Y38)) | AB38: =IF($Y38=0,"",YEAR($Y38))
A39: PAULA RAMOS C. da S. PRADO | B39: 29087248-0 | C39: 259.283.388-99 | D39: 11-983776061 | E39: RUA DESEMBARGADOR DO VALE 932 AP 61 | F39: PERDIZES | G39: SÃO PAULO | H39: 05010-040 | I39: poletecalvoso@gmail.com | J39: PIRATA | K39: 1 | L39: 42396 | M39: =DAY(L39) -> 27 | N39: =MONTH(L39) -> 1 | O39: =YEAR(L39) -> 2016 | Q39: 480 | U39: EMITIDO BOLETO FEV16 | X39: POR 02 MESES | Z39: =IF($Y39=0,"",DAY($Y39)) | AA39: =IF($Y39=0,"",MONTH($Y39)) | AB39: =IF($Y39=0,"",YEAR($Y39))
A40: ANDREA APARECIDA MARTINS PEREIRA | B40: 21565970 | C40: 130.430.778-65 | D40: 11 27379664 | E40: RUA IMBITUBA, 205 BLC 05 APTO 32 | F40: VILA PRUDENTE | G40: SÃO PAULO | H40: 03132-090 | I40: andy_mpereira@hotmail.com | J40: BOBY | K40: 1 | L40: 42393 | M40: =DAY(L40) -> 24 | N40: =MONTH(L40) -> 1 | O40: =YEAR(L40) -> 2016 | Q40: 480 | R40: =Q40*5 -> 2400 | U40: EMITIDO DE FEV A JUN16 | Z40: =IF($Y40=0,"",DAY($Y40)) | AA40: =IF($Y40=0,"",MONTH($Y40)) | AB40: =IF($Y40=0,"",YEAR($Y40))
...

Sheet Total de cães por mês
A3: Ano | C3: Jan | D3: Fev | E3: Mar | F3: Abr | G3: Mai | H3: Jun | I3: Jul | J3: Ago | K3: Set | L3: Out | M3: Nov | N3: Dez | O3: TOTAL
C4: 1 | D4: 2 | E4: 3 | F4: 4 | G4: 5 | H4: 6 | I4: 7 | J4: 8 | K4: 9 | L4: 10 | M4: 11 | N4: 12
A5: 2010 | C5: =SUMIFS(Lista!$K:$K,Lista!$O:$O,$A5,Lista!$N:$N,C$4)+SUMIFS('Ex residentes'!$K:$K,'Ex residentes'!$O:$O,$A5,'Ex residentes'!$N:$N,C$4) -> 0 | D5: =SUMIFS(Lista!$K:$K,Lista!$O:$O,$A5,Lista!$N:$N,D$4)+SUMIFS('Ex residentes'!$K:$K,'Ex residentes'!$O:$O,$A5,'Ex residentes'!$N:$N,D$4) -> 0 | E5: =SUMIFS(Lista!$K:$K,Lista!$O:$O,$A5,Lista!$N:$N,E$4)+SUMIFS('Ex residentes'!$K:$K,'Ex residentes'!$O:$O,$A5,'Ex residentes'!$N:$N,E$4) -> 0 | F5: =SUMIFS(Lista!$K:$K,Lista!$O:$O,$A5,Lista!$N:$N,F$4)+SUMIFS('Ex residentes'!$K:$K,'Ex residentes'!$O:$O,$A5,'Ex residentes'!$N:$N,F$4) -> 0 | G5: =SUMIFS(Lista!$K:$K,Lista!$O:$O,$A5,Lista!$N:$N,G$4)+SUMIFS('Ex residentes'!$K:$K,'Ex residentes'!$O:$O,$A5,'Ex residentes'!$N:$N,G$4) -> 0 | H5: =SUMIFS(Lista!$K:$K,Lista!$O:$O,$A5,Lista!$N:$N,H$4)+SUMIFS('Ex residentes'!$K:$K,'Ex residentes'!$O:$O,$A5,'Ex residentes'!$N:$N,H$4) -> 0 | I5: =SUMIFS(Lista!$K:$K,Lista!$O:$O,$A5,Lista!$N:$N,I$4)+SUMIFS('Ex residentes'!$K:$K,'Ex residentes'!$O:$O,$A5,'Ex residentes'!$N:$N,I$4) -> 0 | J5: =SUMIFS(Lista!$K:$K,Lista!$O:$O,$A5,Lista!$N:$N,J$4)+SUMIFS('Ex residentes'!$K:$K,'Ex residentes'!$O:$O,$A5,'Ex residentes'!$N:$N,J$4) -> 0 | ... N5: =SUMIFS(Lista!$K:$K,Lista!$O:$O,$A5,Lista!$N:$N,N$4)+SUMIFS('Ex residentes'!$K:$K,'Ex residentes'!$O:$O,$A5,'Ex residentes'!$N:$N,N$4) -> 0 | O5: =SUM(C5:N5) -> 7
A6: 2011 | C6: =SUMIFS(Lista!$K:$K,Lista!$O:$O,$A6,Lista!$N:$N,C$4)+SUMIFS('Ex residentes'!$K:$K,'Ex residentes'!$O:$O,$A6,'Ex residentes'!$N:$N,C$4) -> 1 | D6: =SUMIFS(Lista!$K:$K,Lista!$O:$O,$A6,Lista!$N:$N,D$4)+SUMIFS('Ex residentes'!$K:$K,'Ex residentes'!$O:$O,$A6,'Ex residentes'!$N:$N,D$4) -> 0 | E6: =SUMIFS(Lista!$K:$K,Lista!$O:$O,$A6,Lista!$N:$N,E$4)+SUMIFS('Ex residentes'!$K:$K,'Ex residentes'!$O:$O,$A6,'Ex residentes'!$N:$N,E$4) -> 0 | F6: =SUMIFS(Lista!$K:$K,Lista!$O:$O,$A6,Lista!$N:$N,F$4)+SUMIFS('Ex residentes'!$K:$K,'Ex residentes'!$O:$O,$A6,'Ex residentes'!$N:$N,F$4) -> 0 | G6: =SUMIFS(Lista!$K:$K,Lista!$O:$O,$A6,Lista!$N:$N,G$4)+SUMIFS('Ex residentes'!$K:$K,'Ex residentes'!$O:$O,$A6,'Ex residentes'!$N:$N,G$4) -> 1 | H6: =SUMIFS(Lista!$K:$K,Lista!$O:$O,$A6,Lista!$N:$N,H$4)+SUMIFS('Ex residentes'!$K:$K,'Ex residentes'!$O:$O,$A6,'Ex residentes'!$N:$N,H$4) -> 2 | I6: =SUMIFS(Lista!$K:$K,Lista!$O:$O,$A6,Lista!$N:$N,I$4)+SUMIFS('Ex residentes'!$K:$K,'Ex residentes'!$O:$O,$A6,'Ex residentes'!$N:$N,I$4) -> 0 | J6: =SUMIFS(Lista!$K:$K,Lista!$O:$O,$A6,Lista!$N:$N,J$4)+SUMIFS('Ex residentes'!$K:$K,'Ex residentes'!$O:$O,$A6,'Ex residentes'!$N:$N,J$4) -> 0 | ... N6: =SUMIFS(Lista!$K:$K,Lista!$O:$O,$A6,Lista!$N:$N,N$4)+SUMIFS('Ex residentes'!$K:$K,'Ex residentes'!$O:$O,$A6,'Ex residentes'!$N:$N,N$4) -> 0 | O6: =SUM(C6:N6) -> 5
A7: 2012 | C7: =SUMIFS(Lista!$K:$K,Lista!$O:$O,$A7,Lista!$N:$N,C$4)+SUMIFS('Ex residentes'!$K:$K,'Ex residentes'!$O:$O,$A7,'Ex residentes'!$N:$N,C$4) -> 1 | D7: =SUMIFS(Lista!$K:$K,Lista!$O:$O,$A7,Lista!$N:$N,D$4)+SUMIFS('Ex residentes'!$K:$K,'Ex residentes'!$O:$O,$A7,'Ex residentes'!$N:$N,D$4) -> 1 | E7: =SUMIFS(Lista!$K:$K,Lista!$O:$O,$A7,Lista!$N:$N,E$4)+SUMIFS('Ex residentes'!$K:$K,'Ex residentes'!$O:$O,$A7,'Ex residentes'!$N:$N,E$4) -> 1 | F7: =SUMIFS(Lista!$K:$K,Lista!$O:$O,$A7,Lista!$N:$N,F$4)+SUMIFS('Ex residentes'!$K:$K,'Ex residentes'!$O:$O,$A7,'Ex residentes'!$N:$N,F$4) -> 2 | G7: =SUMIFS(Lista!$K:$K,Lista!$O:$O,$A7,Lista!$N:$N,G$4)+SUMIFS('Ex residentes'!$K:$K,'Ex residentes'!$O:$O,$A7,'Ex residentes'!$N:$N,G$4) -> 0 | H7: =SUMIFS(Lista!$K:$K,Lista!$O:$O,$A7,Lista!$N:$N,H$4)+SUMIFS('Ex residentes'!$K:$K,'Ex residentes'!$O:$O,$A7,'Ex residentes'!$N:$N,H$4) -> 2 | I7: =SUMIFS(Lista!$K:$K,Lista!$O:$O,$A7,Lista!$N:$N,I$4)+SUMIFS('Ex residentes'!$K:$K,'Ex residentes'!$O:$O,$A7,'Ex residentes'!$N:$N,I$4) -> 0 | J7: =SUMIFS(Lista!$K:$K,Lista!$O:$O,$A7,Lista!$N:$N,J$4)+SUMIFS('Ex residentes'!$K:$K,'Ex residentes'!$O:$O,$A7,'Ex residentes'!$N:$N,J$4) -> 0 | ... N7: =SUMIFS(Lista!$K:$K,Lista!$O:$O,$A7,Lista!$N:$N,N$4)+SUMIFS('Ex residentes'!$K:$K,'Ex residentes'!$O:$O,$A7,'Ex residentes'!$N:$N,N$4) -> 3 | O7: =SUM(C7:N7) -> 12
A8: 2013 | C8: =SUMIFS(Lista!$K:$K,Lista!$O:$O,$A8,Lista!$N:$N,C$4)+SUMIFS('Ex residentes'!$K:$K,'Ex residentes'!$O:$O,$A8,'Ex residentes'!$N:$N,C$4) -> 1 | D8: =SUMIFS(Lista!$K:$K,Lista!$O:$O,$A8,Lista!$N:$N,D$4)+SUMIFS('Ex residentes'!$K:$K,'Ex residentes'!$O:$O,$A8,'Ex residentes'!$N:$N,D$4) -> 1 | E8: =SUMIFS(Lista!$K:$K,Lista!$O:$O,$A8,Lista!$N:$N,E$4)+SUMIFS('Ex residentes'!$K:$K,'Ex residentes'!$O:$O,$A8,'Ex residentes'!$N:$N,E$4) -> 0 | F8: =SUMIFS(Lista!$K:$K,Lista!$O:$O,$A8,Lista!$N:$N,F$4)+SUMIFS('Ex residentes'!$K:$K,'Ex residentes'!$O:$O,$A8,'Ex residentes'!$N:$N,F$4) -> 0 | G8: =SUMIFS(Lista!$K:$K,Lista!$O:$O,$A8,Lista!$N:$N,G$4)+SUMIFS('Ex residentes'!$K:$K,'Ex residentes'!$O:$O,$A8,'Ex residentes'!$N:$N,G$4) -> 0 | H8: =SUMIFS(Lista!$K:$K,Lista!$O:$O,$A8,Lista!$N:$N,H$4)+SUMIFS('Ex residentes'!$K:$K,'Ex residentes'!$O:$O,$A8,'Ex residentes'!$N:$N,H$4) -> 0 | I8: =SUMIFS(Lista!$K:$K,Lista!$O:$O,$A8,Lista!$N:$N,I$4)+SUMIFS('Ex residentes'!$K:$K,'Ex residentes'!$O:$O,$A8,'Ex residentes'!$N:$N,I$4) -> 1 | J8: =SUMIFS(Lista!$K:$K,Lista!$O:$O,$A8,Lista!$N:$N,J$4)+SUMIFS('Ex residentes'!$K:$K,'Ex residentes'!$O:$O,$A8,'Ex residentes'!$N:$N,J$4) -> 1 | ... N8: =SUMIFS(Lista!$K:$K,Lista!$O:$O,$A8,Lista!$N:$N,N$4)+SUMIFS('Ex residentes'!$K:$K,'Ex residentes'!$O:$O,$A8,'Ex residentes'!$N:$N,N$4) -> 0 | O8: =SUM(C8:N8) -> 6
A9: 2014 | C9: =SUMIFS(Lista!$K:$K,Lista!$O:$O,$A9,Lista!$N:$N,C$4)+SUMIFS('Ex residentes'!$K:$K,'Ex residentes'!$O:$O,$A9,'Ex residentes'!$N:$N,C$4) -> 0 | D9: =SUMIFS(Lista!$K:$K,Lista!$O:$O,$A9,Lista!$N:$N,D$4)+SUMIFS('Ex residentes'!$K:$K,'Ex residentes'!$O:$O,$A9,'Ex residentes'!$N:$N,D$4) -> 1 | E9: =SUMIFS(Lista!$K:$K,Lista!$O:$O,$A9,Lista!$N:$N,E$4)+SUMIFS('Ex residentes'!$K:$K,'Ex residentes'!$O:$O,$A9,'Ex residentes'!$N:$N,E$4) -> 1 | F9: =SUMIFS(Lista!$K:$K,Lista!$O:$O,$A9,Lista!$N:$N,F$4)+SUMIFS('Ex residentes'!$K:$K,'Ex residentes'!$O:$O,$A9,'Ex residentes'!$N:$N,F$4) -> 8 | G9: =SUMIFS(Lista!$K:$K,Lista!$O:$O,$A9,Lista!$N:$N,G$4)+SUMIFS('Ex residentes'!$K:$K,'Ex residentes'!$O:$O,$A9,'Ex residentes'!$N:$N,G$4) -> 2 | H9: =SUMIFS(Lista!$K:$K,Lista!$O:$O,$A9,Lista!$N:$N,H$4)+SUMIFS('Ex residentes'!$K:$K,'Ex residentes'!$O:$O,$A9,'Ex residentes'!$N:$N,H$4) -> 0 | I9: =SUMIFS(Lista!$K:$K,Lista!$O:$O,$A9,Lista!$N:$N,I$4)+SUMIFS('Ex residentes'!$K:$K,'Ex residentes'!$O:$O,$A9,'Ex residentes'!$N:$N,I$4) -> 3 | J9: =SUMIFS(Lista!$K:$K,Lista!$O:$O,$A9,Lista!$N:$N,J$4)+SUMIFS('Ex residentes'!$K:$K,'Ex residentes'!$O:$O,$A9,'Ex residentes'!$N:$N,J$4) -> 6 | ... N9: =SUMIFS(Lista!$K:$K,Lista!$O:$O,$A9,Lista!$N:$N,N$4)+SUMIFS('Ex residentes'!$K:$K,'Ex residentes'!$O:$O,$A9,'Ex residentes'!$N:$N,N$4) -> 0 | O9: =SUM(C9:N9) -> 27
A10: 2015 | C10: =SUMIFS(Lista!$K:$K,Lista!$O:$O,$A10,Lista!$N:$N,C$4)+SUMIFS('Ex residentes'!$K:$K,'Ex residentes'!$O:$O,$A10,'Ex residentes'!$N:$N,C$4) -> 2 | D10: =SUMIFS(Lista!$K:$K,Lista!$O:$O,$A10,Lista!$N:$N,D$4)+SUMIFS('Ex residentes'!$K:$K,'Ex residentes'!$O:$O,$A10,'Ex residentes'!$N:$N,D$4) -> 2 | E10: =SUMIFS(Lista!$K:$K,Lista!$O:$O,$A10,Lista!$N:$N,E$4)+SUMIFS('Ex residentes'!$K:$K,'Ex residentes'!$O:$O,$A10,'Ex residentes'!$N:$N,E$4) -> 2 | F10: =SUMIFS(Lista!$K:$K,Lista!$O:$O,$A10,Lista!$N:$N,F$4)+SUMIFS('Ex residentes'!$K:$K,'Ex residentes'!$O:$O,$A10,'Ex residentes'!$N:$N,F$4) -> 4 | G10: =SUMIFS(Lista!$K:$K,Lista!$O:$O,$A10,Lista!$N:$N,G$4)+SUMIFS('Ex residentes'!$K:$K,'Ex residentes'!$O:$O,$A10,'Ex residentes'!$N:$N,G$4) -> 2 | H10: =SUMIFS(Lista!$K:$K,Lista!$O:$O,$A10,Lista!$N:$N,H$4)+SUMIFS('Ex residentes'!$K:$K,'Ex residentes'!$O:$O,$A10,'Ex residentes'!$N:$N,H$4) -> 2 | I10: =SUMIFS(Lista!$K:$K,Lista!$O:$O,$A10,Lista!$N:$N,I$4)+SUMIFS('Ex residentes'!$K:$K,'Ex residentes'!$O:$O,$A10,'Ex residentes'!$N:$N,I$4) -> 1 | J10: =SUMIFS(Lista!$K:$K,Lista!$O:$O,$A10,Lista!$N:$N,J$4)+SUMIFS('Ex residentes'!$K:$K,'Ex residentes'!$O:$O,$A10,'Ex residentes'!$N:$N,J$4) -> 2 | ... N10: =SUMIFS(Lista!$K:$K,Lista!$O:$O,$A10,Lista!$N:$N,N$4)+SUMIFS('Ex residentes'!$K:$K,'Ex residentes'!$O:$O,$A10,'Ex residentes'!$N:$N,N$4) -> 0 | O10: =SUM(C10:N10) -> 26
A11: 2016 | C11: =SUMIFS(Lista!$K:$K,Lista!$O:$O,$A11,Lista!$N:$N,C$4)+SUMIFS('Ex residentes'!$K:$K,'Ex residentes'!$O:$O,$A11,'Ex residentes'!$N:$N,C$4) -> 11 | D11: =SUMIFS(Lista!$K:$K,Lista!$O:$O,$A11,Lista!$N:$N,D$4)+SUMIFS('Ex residentes'!$K:$K,'Ex residentes'!$O:$O,$A11,'Ex residentes'!$N:$N,D$4) -> 6 | E11: =SUMIFS(Lista!$K:$K,Lista!$O:$O,$A11,Lista!$N:$N,E$4)+SUMIFS('Ex residentes'!$K:$K,'Ex residentes'!$O:$O,$A11,'Ex residentes'!$N:$N,E$4) -> 4 | F11: =SUMIFS(Lista!$K:$K,Lista!$O:$O,$A11,Lista!$N:$N,F$4)+SUMIFS('Ex residentes'!$K:$K,'Ex residentes'!$O:$O,$A11,'Ex residentes'!$N:$N,F$4) -> 1 | G11: =SUMIFS(Lista!$K:$K,Lista!$O:$O,$A11,Lista!$N:$N,G$4)+SUMIFS('Ex residentes'!$K:$K,'Ex residentes'!$O:$O,$A11,'Ex residentes'!$N:$N,G$4) -> 1 | H11: =SUMIFS(Lista!$K:$K,Lista!$O:$O,$A11,Lista!$N:$N,H$4)+SUMIFS('Ex residentes'!$K:$K,'Ex residentes'!$O:$O,$A11,'Ex residentes'!$N:$N,H$4) -> 1 | I11: =SUMIFS(Lista!$K:$K,Lista!$O:$O,$A11,Lista!$N:$N,I$4)+SUMIFS('Ex residentes'!$K:$K,'Ex residentes'!$O:$O,$A11,'Ex residentes'!$N:$N,I$4) -> 8 | J11: =SUMIFS(Lista!$K:$K,Lista!$O:$O,$A11,Lista!$N:$N,J$4)+SUMIFS('Ex residentes'!$K:$K,'Ex residentes'!$O:$O,$A11,'Ex residentes'!$N:$N,J$4) -> 7 | ... N11: =SUMIFS(Lista!$K:$K,Lista!$O:$O,$A11,Lista!$N:$N,N$4)+SUMIFS('Ex residentes'!$K:$K,'Ex residentes'!$O:$O,$A11,'Ex residentes'!$N:$N,N$4) -> 2 | O11: =SUM(C11:N11)+1 -> 51 | P11: Média
A12: 2017 | B12: Entrada | C12: =SUMIFS(Lista!$K:$K,Lista!$O:$O,$A12,Lista!$N:$N,C$4)+SUMIFS('Ex residentes'!$K:$K,'Ex residentes'!$O:$O,$A12,'Ex residentes'!$N:$N,C$4) -> 2 | D12: =SUMIFS(Lista!$K:$K,Lista!$O:$O,$A12,Lista!$N:$N,D$4)+SUMIFS('Ex residentes'!$K:$K,'Ex residentes'!$O:$O,$A12,'Ex residentes'!$N:$N,D$4) -> 3 | E12: =SUMIFS(Lista!$K:$K,Lista!$O:$O,$A12,Lista!$N:$N,E$4)+SUMIFS('Ex residentes'!$K:$K,'Ex residentes'!$O:$O,$A12,'Ex residentes'!$N:$N,E$4) -> 5 | F12: =SUMIFS(Lista!$K:$K,Lista!$O:$O,$A12,Lista!$N:$N,F$4)+SUMIFS('Ex residentes'!$K:$K,'Ex residentes'!$O:$O,$A12,'Ex residentes'!$N:$N,F$4) -> 1 | G12: =SUMIFS(Lista!$K:$K,Lista!$O:$O,$A12,Lista!$N:$N,G$4)+SUMIFS('Ex residentes'!$K:$K,'Ex residentes'!$O:$O,$A12,'Ex residentes'!$N:$N,G$4) -> 5 | H12: =SUMIFS(Lista!$K:$K,Lista!$O:$O,$A12,Lista!$N:$N,H$4)+SUMIFS('Ex residentes'!$K:$K,'Ex residentes'!$O:$O,$A12,'Ex residentes'!$N:$N,H$4) -> 2 | I12: =SUMIFS(Lista!$K:$K,Lista!$O:$O,$A12,Lista!$N:$N,I$4)+SUMIFS('Ex residentes'!$K:$K,'Ex residentes'!$O:$O,$A12,'Ex residentes'!$N:$N,I$4) -> 2 | J12: =SUMIFS(Lista!$K:$K,Lista!$O:$O,$A12,Lista!$N:$N,J$4)+SUMIFS('Ex residentes'!$K:$K,'Ex residentes'!$O:$O,$A12,'Ex residentes'!$N:$N,J$4) -> 6 | ... N12: =SUMIFS(Lista!$K:$K,Lista!$O:$O,$A12,Lista!$N:$N,N$4)+SUMIFS('Ex residentes'!$K:$K,'Ex residentes'!$O:$O,$A12,'Ex residentes'!$N:$N,N$4) -> 0 | O12: =SUM(C12:N12) -> 37 | P12: =AVERAGE(C12:N12) -> 3.0833333
B13: Saída | C13: =SUMIFS('Ex residentes'!$K:$K,'Ex residentes'!$AB:$AB,$A12,'Ex residentes'!$AA:$AA,C$4) -> 7 | D13: =SUMIFS('Ex residentes'!$K:$K,'Ex residentes'!$AB:$AB,$A12,'Ex residentes'!$AA:$AA,D$4) -> 1 | E13: =SUMIFS('Ex residentes'!$K:$K,'Ex residentes'!$AB:$AB,$A12,'Ex residentes'!$AA:$AA,E$4) -> 1 | F13: =SUMIFS('Ex residentes'!$K:$K,'Ex residentes'!$AB:$AB,$A12,'Ex residentes'!$AA:$AA,F$4) -> 6 | G13: =SUMIFS('Ex residentes'!$K:$K,'Ex residentes'!$AB:$AB,$A12,'Ex residentes'!$AA:$AA,G$4) -> 1 | H13: =SUMIFS('Ex residentes'!$K:$K,'Ex residentes'!$AB:$AB,$A12,'Ex residentes'!$AA:$AA,H$4) -> 4 | I13: =SUMIFS('Ex residentes'!$K:$K,'Ex residentes'!$AB:$AB,$A12,'Ex residentes'!$AA:$AA,I$4) -> 4 | J13: =SUMIFS('Ex residentes'!$K:$K,'Ex residentes'!$AB:$AB,$A12,'Ex residentes'!$AA:$AA,J$4) -> 2 | ... N13: =SUMIFS('Ex residentes'!$K:$K,'Ex residentes'!$AB:$AB,$A12,'Ex residentes'!$AA:$AA,N$4) -> 8 | O13: =SUM(C13:N13) -> 37 | P13: =AVERAGE(C13:N13) -> 3.0833333
B14: Total de cães | C14: =O11 -> 51 | D14: =C14+D12-D13 -> 53 | E14: =D14+E12-E13 -> 57 | F14: =E14+F12-F13 -> 52 | G14: =F14+G12-G13 -> 56 | H14: =G14+H12-H13 -> 54 | I14: =H14+I12-I13 -> 52 | J14: =I14+J12-J13 -> 56 | K14: =J14+K12-K13 -> 57 | ... N14: =M14+N12-N13 -> 56 | O14: =O12-O13 -> 0 | P14: =AVERAGE(C14:N14) -> 55.583333
